Workbook

Sheet Feuil1
A1: Q1 : Êtes-vous | B1: Q2 : Si vous avez coché sage-femme diplômé(e), depuis combien de temps exercez-vous ? | C1: Q3 : Dans quelle structure exercez-vous ? | D1: Q4 : Sur une échelle de 1 à 5, comment évalueriez-vous votre niveau de connaissance de l’ostéopathie ? | E1: Q5 : Quelle est selon vous, la place de l’ostéopathie dans la prise en charge globale de la femme enceinte ? | F1: Q6 : Vous sentez-vous suffisamment informé(e) sur l’ostéopathie et ses indications durant la grossesse ? | G1: Q7 : Avez-vous accès, au sein de votre structure, à un réseau d’ostéopathes vers lesquels orienter vos patientes ? | H1: Q8 : La collaboration avec un(e) ostéopathe fait-elle partie intégrante de votre pratique ? | I1: Q9 : Si oui, dans quel(s) cadre(s) ? | J1: Q10 : Comment estimez-vous vos connaissances concernant le syndrome de Lacomme (douleurs ligamentaires lombo-pelviennes de grossesse) ? | K1: Q11 : Comment identifiez-vous ce syndrome dans votre pratique ? | L1: Q12 : A quelle fréquence rencontrez-vous des patientes présentant un syndrome de Lacomme ? | M1: Q13 : Estimez-vous qu’il y a un retard diagnostic à la prise en charge de ce syndrome ? | N1: Q14 : Si oui, quelles sont les principales raisons de ce retard diagnostic ? | O1: Q15 : Classez les différentes prises en charge dans l’ordre que vous recommanderiez pour une patiente atteinte du syndrome de Lacomme : [Premier choix ] | P1: Q15 : Classez les différentes prises en charge dans l’ordre que vous recommanderiez pour une patiente atteinte du syndrome de Lacomme : [Second choix ] | Q1: Q15 : Classez les différentes prises en charge dans l’ordre que vous recommanderiez pour une patiente atteinte du syndrome de Lacomme : [Troisième choix ] | R1: Q15 : Classez les différentes prises en charge dans l’ordre que vous recommanderiez pour une patiente atteinte du syndrome de Lacomme : [Quatrième choix ] | S1: Q15 : Classez les différentes prises en charge dans l’ordre que vous recommanderiez pour une patiente atteinte du syndrome de Lacomme : [Cinquième choix ] | T1: Q15 : Classez les différentes prises en charge dans l’ordre que vous recommanderiez pour une patiente atteinte du syndrome de Lacomme : [Sixième choix ] | U1: Q16 : Pensez-vous que l'ostéopathie constitue une approche pertinente pour traiter le syndrome de Lacomme et qu’elle mérite d’être recommandée aux patientes concernées ? | V1: Q17 : Si oui, à quel moment ? | W1: Q18 : Pensez-vous que les patientes sont suffisamment informées sur les possibilités de prises en charge ostéopathiques du syndrome de Lacomme ? | X1: Q19 : Quels sont les facteurs qui permettraient de favoriser l’intégration de l’ostéopathie dans la prise en charge du syndrome de Lacomme ? | Y1: Q20 : Quels sont, selon vous, les freins à l’intégration de l’ostéopathie dans la pratique sage-femme ? | Z1: Q21 : Quels sont les facteurs qui influencent votre décision de recommander ou non l’ostéopathie ? | AA1: Q22 : Les recommandations officielles (HAS, CNGOF, Ordre des sages-femmes) influencent-elles votre décision d’orienter vers l’ostéopathie ? | AB1: Q23 : Pensez-vous que la collaboration entre sages-femmes et ostéopathes pourrait améliorer la prise en charge des femmes enceintes ? | AC1: Q24 : Seriez-vous favorable à l’intégration d’ostéopathes dans les équipes pluridisciplinaires périnatales ? | AD1: Q25 : Quels éléments pourraient favoriser une meilleure collaboration entre sages-femmes et ostéopathes ? | AE1: Q26 : Souhaitez-vous partager une expérience ou un avis personnel concernant l’ostéopathie dans la prise en charge du syndrome de Lacomme ? | AF1: Q26 : Souhaitez-vous partager une expérience ou un avis personnel concernant l’ostéopathie dans la prise en charge du syndrome de Lacomme ? | AG1: Q27 : Souhaitez-vous partager une expérience ou un avis personnel concernant l’ostéopathie et la collaboration avec les sages-femmes ? | AH1: Q27 : Souhaitez-vous partager une expérience ou un avis personnel concernant l’ostéopathie et la collaboration avec les sages-femmes ? | AI1: Q28 : Y a-t-il un élément ou un commentaire supplémentaire que vous souhaiteriez apporter ? | AJ1: Q28 : Y a-t-il un élément ou un commentaire supplémentaire que vous souhaiteriez apporter ?
A2: Étudiant(e) sage-femme en 5e année | B2: 0 | C2: 0 | D2: 4 | E2: 4 | F2: 3 | G2: Oui | H2: Oui, occasionnellement (> ou = à 1 fois par mois) | I2: Douleurs lombaires et/ou pelviennes, Post-partum, Allaitement, Nouveau-né | J2: 4 | K2: Interrogatoire | L2: A chaque suivi | M2: Oui | N2: Absence de recommandations professionnelles claires | O2: Exercices/Etirements | P2: Ostéopathie | Q2: Conseils posturaux | R2: Traitements médicamenteux (antalgiques/analgésiques) | S2: Ceinture de maintien/Support pelvien | T2: Repos/Limitation de mouvement | U2: 5 | V2: Dès les premiers symptômes | W2: 1 | X2: Preuves scientifiques, Réduction du coût des séances pour les patientes, Reconnaissance institutionnelle | Y2: Peu de contenus pédagogiques sur les principes ostéopathiques inscrits au parcours académique, Absence de connaissances sur la pratique ostéopathique, Insuffisance de preuves scientifiques, Coût pour les patientes, Absence de reconnaissance institutionnelle | Z2: Motivation des patientes pour une prise en charge manuelle complémentaire | AA2: Oui | AB2: Oui | AC2: Oui | AD2: Preuves de résultats positifs des traitements ostéopathiques, Demande des patientes, Encadrement institutionnel et recommandations officielles | AE2: Le syndrome de Lacomme est beaucoup expliqué par les SF comme « maux qui font partie des symptômes de la grossesse » et donc plutôt un discours de « ça passera » | AF2: Banalisation du syndrome de Lacomme, Absence de connaissances sur le syndrome de Lacomme | AG2: 0 | AH2: 0 | AI2: 0 | AJ2: 0
A3: Étudiant(e) sage-femme en 5e année | B3: 0 | C3: 0 | D3: 2 | E3: 3 | F3: 3 | G3: Oui | H3: Oui, occasionnellement (> ou = à 1 fois par mois) | I3: Suivi prénatal de grossesse, Douleurs lombaires et/ou pelviennes | J3: 2 | K3: Interrogatoire | L3: Rarement (> ou = à 1 fois tous les 3 mois) | M3: Sans avis | N3: 0 | O3: Conseils posturaux | P3: Exercices/Etirements | Q3: Ceinture de maintien/Support pelvien | R3: Ostéopathie | S3: Traitements médicamenteux (antalgiques/analgésiques) | T3: Repos/Limitation de mouvement | U3: 4 | V3: En cas d’absence de réussite d’autres prises en charge | W3: 2 | X3: Contenus pédagogiques sur les principes ostéopathiques inscrits au parcours académique, Réduction du coût des séances pour les patientes, Intégration de l’ostéopathie dans les structures de santé | Y3: Absence de connaissances sur la pratique ostéopathique, Insuffisance de collaboration interprofessionnelle avec des ostéopathes, Coût pour les patientes, Absence de reconnaissance institutionnelle | Z3: Caractère chronique ou aigu des douleurs, Spécialisation de l’ostéopathe en périnatalité, Motivation des patientes pour une prise en charge manuelle complémentaire, Disponibilité et/ou accessibilité d’ostéopathes dans votre réseau, Collaboration interprofessionnelle préexistante, Convictions personnelles concernant cette approche thérapeutique | AA3: Sans avis | AB3: Oui | AC3: Oui | AD3: Preuves de résultats positifs des traitements ostéopathiques, Formations sémiologiques supplémentaires des ostéopathes, Mise en place de protocoles règlementés | AE3: 0 | AF3: 0 | AG3: 0 | AH3: 0 | AI3: 0 | AJ3: 0
A4: Étudiant(e) sage-femme en 5e année | B4: 0 | C4: 0 | D4: 2 | E4: 3 | F4: 2 | G4: Non | H4: Non | I4: 0 | J4: 4 | K4: Interrogatoire, Examen clinique, En excluant d’autres causes possibles de douleurs pelviennes pendant la grossesse | L4: Rarement (> ou = à 1 fois tous les 3 mois) | M4: Sans avis | N4: Absence de formation spécifique sur le syndrome, Assimilation du syndrome à des lombalgies non spécifiques | O4: Conseils posturaux | P4: Ostéopathie | Q4: Exercices/Etirements | R4: Ceinture de maintien/Support pelvien | S4: Repos/Limitation de mouvement | T4: Traitements médicamenteux (antalgiques/analgésiques) | U4: 4 | V4: Dès les premiers symptômes | W4: 2 | X4: Contenus pédagogiques sur les principes ostéopathiques inscrits au parcours académique, Preuves scientifiques, Réduction du coût des séances pour les patientes | Y4: Peu de contenus pédagogiques sur les principes ostéopathiques inscrits au parcours académique, Absence de connaissances sur la pratique ostéopathique, Insuffisance de preuves scientifiques, Coût pour les patientes | Z4: Spécialisation de l’ostéopathe en périnatalité, Motivation des patientes pour une prise en charge manuelle complémentaire | AA4: Oui | AB4: Oui | AC4: Oui | AD4: Preuves de résultats positifs des traitements ostéopathiques, Encadrement institutionnel et recommandations officielles | AE4: 0 | AF4: 0 | AG4: 0 | AH4: 0 | AI4: 0 | AJ4: 0
A5: Étudiant(e) sage-femme en 5e année | B5: 0 | C5: 0 | D5: 1 | E5: 4 | F5: 2 | G5: Non | H5: Oui, occasionnellement (> ou = à 1 fois par mois) | I5: Douleurs lombaires et/ou pelviennes | J5: 2 | K5: Interrogatoire, Examen clinique | L5: Occasionnellement (> ou = à 1 fois par mois) | M5: Oui | N5: Sous-estimation des plaintes des patientes | O5: Conseils posturaux | P5: Repos/Limitation de mouvement, Conseils posturaux | Q5: Exercices/Etirements | R5: Ceinture de maintien/Support pelvien | S5: Ostéopathie | T5: Traitements médicamenteux (antalgiques/analgésiques) | U5: 5 | V5: Dès les premiers symptômes | W5: 3 | X5: Contenus pédagogiques sur les principes ostéopathiques inscrits au parcours académique, Reconnaissance institutionnelle | Y5: Peu de contenus pédagogiques sur les principes ostéopathiques inscrits au parcours académique, Absence de connaissances sur la pratique ostéopathique | Z5: Motivation des patientes pour une prise en charge manuelle complémentaire | AA5: Oui | AB5: Oui | AC5: Oui | AD5: Mise en place de protocoles règlementés, Encadrement institutionnel et recommandations officielles | AE5: 0 | AF5: 0 | AG5: 0 | AH5: 0 | AI5: 0 | AJ5: 0
A6: Étudiant(e) sage-femme en 5e année | B6: 0 | C6: 0 | D6: 1 | E6: 3 | F6: 2 | G6: Oui | H6: Oui, occasionnellement (> ou = à 1 fois par mois) | I6: Douleurs lombaires et/ou pelviennes, Post-partum | J6: 4 | K6: Interrogatoire, Examen clinique, En excluant d’autres causes possibles de douleurs pelviennes pendant la grossesse | L6: Rarement (> ou = à 1 fois tous les 3 mois) | M6: Oui | N6: Absence de formation spécifique sur le syndrome, Assimilation du syndrome à des lombalgies non spécifiques | O6: Conseils posturaux | P6: Exercices/Etirements | Q6: Ceinture de maintien/Support pelvien | R6: Ostéopathie | S6: Repos/Limitation de mouvement | T6: Traitements médicamenteux (antalgiques/analgésiques) | U6: 4 | V6: En cas d’absence de réussite d’autres prises en charge | W6: 1 | X6: Contenus pédagogiques sur les principes ostéopathiques inscrits au parcours académique, Retours de patientes, Preuves scientifiques, Médiatisation/Réseaux sociaux, Réduction du coût des séances pour les patientes, Reconnaissance institutionnelle, Intégration de l’ostéopathie dans les structures de santé | Y6: Peu de contenus pédagogiques sur les principes ostéopathiques inscrits au parcours académique, Absence de connaissances sur la pratique ostéopathique, Insuffisance de preuves scientifiques | Z6: Caractère chronique ou aigu des douleurs, Réponse ou non aux autres traitements, Motivation des patientes pour une prise en charge manuelle complémentaire, Disponibilité et/ou accessibilité d’ostéopathes dans votre réseau | AA6: Sans avis | AB6: Oui | AC6: Oui | AD6: Preuves de résultats positifs des traitements ostéopathiques, Demande des patientes, Formations sémiologiques supplémentaires des ostéopathes, Recommandations par d’autres professionnels de santé, Absence ou inefficacité d’autres solutions thérapeutiques, Mise en place de protocoles règlementés, Encadrement institutionnel et recommandations officielles | AE6: 0 | AF6: 0 | AG6: 0 | AH6: 0 | AI6: 0 | AJ6: 0
A7: Étudiant(e) sage-femme en 5e année | B7: 0 | C7: 0 | D7: 4 | E7: 4 | F7: 4 | G7: Non | H7: Oui, occasionnellement (> ou = à 1 fois par mois) | I7: Suivi prénatal de grossesse, Douleurs lombaires et/ou pelviennes, Post-partum | J7: 3 | K7: Interrogatoire, Examen clinique, En excluant d’autres causes possibles de douleurs pelviennes pendant la grossesse | L7: Rarement (> ou = à 1 fois tous les 3 mois) | M7: Non | N7: 0 | O7: Exercices/Etirements | P7: Ceinture de maintien/Support pelvien | Q7: Ostéopathie | R7: Conseils posturaux | S7: Repos/Limitation de mouvement | T7: Traitements médicamenteux (antalgiques/analgésiques) | U7: 4 | V7: Dès les premiers symptômes | W7: 3 | X7: Retours de patientes, Intégration de l’ostéopathie dans les structures de santé | Y7: Peu de contenus pédagogiques sur les principes ostéopathiques inscrits au parcours académique, Absence de connaissances sur la pratique ostéopathique, Insuffisance de preuves scientifiques, Coût pour les patientes | Z7: Caractère chronique ou aigu des douleurs, Spécialisation de l’ostéopathe en périnatalité, Motivation des patientes pour une prise en charge manuelle complémentaire, Expérience personnelle antérieure positive ou négative avec l’ostéopathie | AA7: Sans avis | AB7: Oui | AC7: Oui | AD7: Preuves de résultats positifs des traitements ostéopathiques | AE7: 0 | AF7: 0 | AG7: 0 | AH7: 0 | AI7: 0 | AJ7: 0
A8: Étudiant(e) sage-femme en 5e année | B8: 0 | C8: Mixte | D8: 1 | E8: 3 | F8: 1 | G8: Non | H8: Oui, rarement (< à 1 fois par mois) | I8: Douleurs lombaires et/ou pelviennes, Nouveau-né | J8: 2 | K8: Interrogatoire, En excluant d’autres causes possibles de douleurs pelviennes pendant la grossesse | L8: Rarement (> ou = à 1 fois tous les 3 mois) | M8: Oui | N8: Absence de formation spécifique sur le syndrome, Sous-estimation des plaintes des patientes | O8: Conseils posturaux | P8: Exercices/Etirements | Q8: Ceinture de maintien/Support pelvien | R8: Ostéopathie | S8: Traitements médicamenteux (antalgiques/analgésiques) | T8: Repos/Limitation de mouvement | U8: 4 | V8: Dès les premiers symptômes | W8: 2 | X8: Contenus pédagogiques sur les principes ostéopathiques inscrits au parcours académique, Preuves scientifiques, Médiatisation/Réseaux sociaux, Réduction du coût des séances pour les patientes | Y8: Peu de contenus pédagogiques sur les principes ostéopathiques inscrits au parcours académique, Insuffisance de collaboration interprofessionnelle avec des ostéopathes, Coût pour les patientes | Z8: Caractère chronique ou aigu des douleurs, Réponse ou non aux autres traitements, Spécialisation de l’ostéopathe en périnatalité, Motivation des patientes pour une prise en charge manuelle complémentaire, Disponibilité et/ou accessibilité d’ostéopathes dans votre réseau | AA8: Oui | AB8: Oui | AC8: Oui | AD8: Preuves de résultats positifs des traitements ostéopathiques, Demande des patientes, Formations sémiologiques supplémentaires des ostéopathes, Mise en place de protocoles règlementés, Encadrement institutionnel et recommandations officielles | AE8: 0 | AF8: 0 | AG8: 0 | AH8: 0 | AI8: 0 | AJ8: 0
A9: Étudiant(e) sage-femme en 5e année | B9: 0 | C9: 0 | D9: 2 | E9: 4 | F9: 1 | G9: Oui | H9: Non | I9: Douleurs lombaires et/ou pelviennes | J9: 4 | K9: Interrogatoire, Examen clinique, En excluant d’autres causes possibles de douleurs pelviennes pendant la grossesse | L9: Fréquemment (> ou = à 1 fois par semaine) | M9: Oui | N9: Absence de formation spécifique sur le syndrome, Sous-estimation des plaintes des patientes, Absence de recommandations professionnelles claires | O9: Conseils posturaux | P9: Exercices/Etirements | Q9: Ostéopathie | R9: Traitements médicamenteux (antalgiques/analgésiques) | S9: Ceinture de maintien/Support pelvien | T9: Repos/Limitation de mouvement | U9: 5 | V9: Dès les premiers symptômes | W9: 1 | X9: Contenus pédagogiques sur les principes ostéopathiques inscrits au parcours académique, Retours de patientes, Reconnaissance institutionnelle, Intégration de l’ostéopathie dans les structures de santé | Y9: Peu de contenus pédagogiques sur les principes ostéopathiques inscrits au parcours académique, Absence de connaissances sur la pratique ostéopathique, Insuffisance de collaboration interprofessionnelle avec des ostéopathes, Absence de reconnaissance institutionnelle | Z9: Caractère chronique ou aigu des douleurs, Motivation des patientes pour une prise en charge manuelle complémentaire, Collaboration interprofessionnelle préexistante | AA9: Oui | AB9: Oui | AC9: Oui | AD9: Preuves de résultats positifs des traitements ostéopathiques, Demande des patientes, Mise en place de protocoles règlementés, Encadrement institutionnel et recommandations officielles | AE9: 0 | AF9: 0 | AG9: 0 | AH9: 0 | AI9: 0 | AJ9: 0
A10: Étudiant(e) sage-femme en 5e année | B10: 0 | C10: 0 | D10: 3 | E10: 4 | F10: 4 | G10: Oui | H10: Oui, occasionnellement (> ou = à 1 fois par mois) | I10: Douleurs lombaires et/ou pelviennes, Troubles digestifs associés, Post-partum, Allaitement | J10: 4 | K10: Interrogatoire, Examen clinique, En excluant d’autres causes possibles de douleurs pelviennes pendant la grossesse | L10: Occasionnellement (> ou = à 1 fois par mois) | M10: Oui | N10: Absence de formation spécifique sur le syndrome, Assimilation du syndrome à des lombalgies non spécifiques, Difficultés d’accès aux thérapies non médicamenteuses, Absence de recommandations professionnelles claires | O10: Conseils posturaux | P10: Exercices/Etirements | Q10: Ceinture de maintien/Support pelvien | R10: Ostéopathie | S10: Traitements médicamenteux (antalgiques/analgésiques) | T10: Repos/Limitation de mouvement | U10: 5 | V10: En cas d’absence de réussite d’autres prises en charge | W10: 2 | X10: Preuves scientifiques, Réduction du coût des séances pour les patientes, Reconnaissance institutionnelle, Intégration de l’ostéopathie dans les structures de santé | Y10: Absence de connaissances sur la pratique ostéopathique, Coût pour les patientes, Absence de reconnaissance institutionnelle | Z10: Caractère chronique ou aigu des douleurs, Réponse ou non aux autres traitements, Spécialisation de l’ostéopathe en périnatalité, Motivation des patientes pour une prise en charge manuelle complémentaire, Disponibilité et/ou accessibilité d’ostéopathes dans votre réseau | AA10: 0 | AB10: Oui | AC10: Oui | AD10: Preuves de résultats positifs des traitements ostéopathiques, Formations sémiologiques supplémentaires des ostéopathes, Absence ou inefficacité d’autres solutions thérapeutiques, Mise en place de protocoles règlementés, Encadrement institutionnel et recommandations officielles | AE10: 0 | AF10: 0 | AG10: 0 | AH10: 0 | AI10: 0 | AJ10: 0
A11: Étudiant(e) sage-femme en 5e année | B11: 0 | C11: 0 | D11: 1 | E11: 3 | F11: 3 | G11: Oui | H11: Non | I11: Douleurs lombaires et/ou pelviennes, Post-partum, Allaitement | J11: 2 | K11: Interrogatoire, En excluant d’autres causes possibles de douleurs pelviennes pendant la grossesse | L11: Jamais | M11: Sans avis | N11: Absence de formation spécifique sur le syndrome, Assimilation du syndrome à des lombalgies non spécifiques, Absence de recommandations professionnelles claires | O11: Repos/Limitation de mouvement | P11: Ceinture de maintien/Support pelvien | Q11: Conseils posturaux | R11: Ostéopathie | S11: Exercices/Etirements | T11: Traitements médicamenteux (antalgiques/analgésiques) | U11: 4 | V11: En cas d’absence de réussite d’autres prises en charge | W11: 1 | X11: Contenus pédagogiques sur les principes ostéopathiques inscrits au parcours académique, Preuves scientifiques, Médiatisation/Réseaux sociaux, Réduction du coût des séances pour les patientes, Intégration de l’ostéopathie dans les structures de santé | Y11: Peu de contenus pédagogiques sur les principes ostéopathiques inscrits au parcours académique, Absence de connaissances sur la pratique ostéopathique, Insuffisance de preuves scientifiques, Insuffisance de collaboration interprofessionnelle avec des ostéopathes | Z11: Caractère chronique ou aigu des douleurs, Réponse ou non aux autres traitements, Spécialisation de l’ostéopathe en périnatalité, Motivation des patientes pour une prise en charge manuelle complémentaire, Disponibilité et/ou accessibilité d’ostéopathes dans votre réseau, Collaboration interprofessionnelle préexistante, Convictions personnelles concernant cette approche thérapeutique, Expérience personnelle antérieure positive ou négative avec l’ostéopathie | AA11: Oui | AB11: Oui | AC11: Oui | AD11: Formations sémiologiques supplémentaires des ostéopathes, Recommandations par d’autres professionnels de santé | AE11: 0 | AF11: 0 | AG11: 0 | AH11: 0 | AI11: 0 | AJ11: 0
A12: Étudiant(e) sage-femme en 5e année | B12: 0 | C12: 0 | D12: 3 | E12: 4 | F12: 4 | G12: Sans avis | H12: Oui, occasionnellement (> ou = à 1 fois par mois) | I12: Suivi prénatal de grossesse, Préparation à l’accouchement, Douleurs lombaires et/ou pelviennes, Post-partum | J12: 2 | K12: Interrogatoire, Examen clinique, En excluant d’autres causes possibles de douleurs pelviennes pendant la grossesse | L12: Rarement (> ou = à 1 fois tous les 3 mois) | M12: Sans avis | N12: Absence de formation spécifique sur le syndrome, Difficultés d’accès aux thérapies non médicamenteuses, Absence de recommandations professionnelles claires | O12: Exercices/Etirements | P12: Conseils posturaux | Q12: Ceinture de maintien/Support pelvien | R12: Ostéopathie | S12: Traitements médicamenteux (antalgiques/analgésiques) | T12: Repos/Limitation de mouvement | U12: 4 | V12: Dès les premiers symptômes | W12: 2 | X12: Contenus pédagogiques sur les principes ostéopathiques inscrits au parcours académique, Retours de patientes, Preuves scientifiques, Réduction du coût des séances pour les patientes | Y12: Insuffisance de preuves scientifiques, Insuffisance de collaboration interprofessionnelle avec des ostéopathes, Coût pour les patientes | Z12: Caractère chronique ou aigu des douleurs, Réponse ou non aux autres traitements, Motivation des patientes pour une prise en charge manuelle complémentaire, Disponibilité et/ou accessibilité d’ostéopathes dans votre réseau | AA12: Oui | AB12: Oui | AC12: Oui | AD12: Preuves de résultats positifs des traitements ostéopathiques, Demande des patientes, Absence ou inefficacité d’autres solutions thérapeutiques, Mise en place de protocoles règlementés | AE12: 0 | AF12: 0 | AG12: 0 | AH12: 0 | AI12: 0 | AJ12: 0
A13: Étudiant(e) sage-femme en 5e année | B13: 0 | C13: 0 | D13: 1 | E13: 3 | F13: 1 | G13: Sans avis | H13: Non | I13: 0 | J13: 2 | K13: Interrogatoire, Examen clinique, En excluant d’autres causes possibles de douleurs pelviennes pendant la grossesse | L13: Jamais | M13: Oui | N13: Absence de formation spécifique sur le syndrome | O13: Repos/Limitation de mouvement | P13: Conseils posturaux | Q13: Exercices/Etirements | R13: Ceinture de maintien/Support pelvien | S13: Traitements médicamenteux (antalgiques/analgésiques) | T13: Ostéopathie | U13: 4 | V13: En cas d’absence de réussite d’autres prises en charge | W13: 1 | X13: Contenus pédagogiques sur les principes ostéopathiques inscrits au parcours académique, Preuves scientifiques, Réduction du coût des séances pour les patientes, Intégration de l’ostéopathie dans les structures de santé | Y13: Peu de contenus pédagogiques sur les principes ostéopathiques inscrits au parcours académique, Absence de connaissances sur la pratique ostéopathique, Insuffisance de collaboration interprofessionnelle avec des ostéopathes | Z13: Caractère chronique ou aigu des douleurs, Réponse ou non aux autres traitements, Spécialisation de l’ostéopathe en périnatalité, Motivation des patientes pour une prise en charge manuelle complémentaire, Disponibilité et/ou accessibilité d’ostéopathes dans votre réseau, Collaboration interprofessionnelle préexistante, Convictions personnelles concernant cette approche thérapeutique | AA13: Non | AB13: Oui | AC13: Oui | AD13: Demande des patientes, Formations sémiologiques supplémentaires des ostéopathes, Absence ou inefficacité d’autres solutions thérapeutiques, Mise en place de protocoles règlementés, Encadrement institutionnel et recommandations officielles | AE13: 0 | AF13: 0 | AG13: 0 | AH13: 0 | AI13: 0 | AJ13: 0
A14: Sage-femme diplômé(e) | B14: Moins de 2 ans | C14: Hospitalier | D14: 4 | E14: 5 | F14: 3 | G14: Non | H14: Oui, occasionnellement (> ou = à 1 fois par mois) | I14: Suivi prénatal de grossesse, Douleurs lombaires et/ou pelviennes, Post-partum | J14: 4 | K14: Interrogatoire, En excluant d’autres causes possibles de douleurs pelviennes pendant la grossesse | L14: Fréquemment (> ou = à 1 fois par semaine) | M14: Non | N14: Assimilation du syndrome à des lombalgies non spécifiques, Absence de recommandations professionnelles claires | O14: Ceinture de maintien/Support pelvien | P14: Conseils posturaux | Q14: Ostéopathie | R14: Exercices/Etirements | S14: Traitements médicamenteux (antalgiques/analgésiques) | T14: Repos/Limitation de mouvement | U14: 5 | V14: Dès les premiers symptômes | W14: 3 | X14: Contenus pédagogiques sur les principes ostéopathiques inscrits au parcours académique, Preuves scientifiques, Reconnaissance institutionnelle, Intégration de l’ostéopathie dans les structures de santé | Y14: Coût pour les patientes, Absence de reconnaissance institutionnelle | Z14: Spécialisation de l’ostéopathe en périnatalité, Motivation des patientes pour une prise en charge manuelle complémentaire, Disponibilité et/ou accessibilité d’ostéopathes dans votre réseau, Collaboration interprofessionnelle préexistante, Convictions personnelles concernant cette approche thérapeutique, Expérience personnelle antérieure positive ou négative avec l’ostéopathie | AA14: Sans avis | AB14: Oui | AC14: Oui | AD14: Demande des patientes, Formations sémiologiques supplémentaires des ostéopathes, Recommandations par d’autres professionnels de santé, Mise en place de protocoles règlementés, Encadrement institutionnel et recommandations officielles | AE14: 0 | AF14: 0 | AG14: J'ai déjà rencontré des ostéopathes et kinésithérapeute spécialisés en périnatalité et c'était très intéressant car ils ont des connaissances en terme de mobilité, posture etc que nous sages femmes n'avons pas du tout. Nous avons tour intérêt à travailler ensemble. | AH14: Favorable à l’intégration de l’ostéopathie, Collaboration interprofessionnelle, Spécialisation en périnatalité | AI14: Étude très intéressante qui mérite d'être publiée dans une revue médicale car l'ostéopathie est encore beaucoup rejeté par certains professionnels de santé | AJ14: Etude intéressante, Intérêt scientifique, Présence de réticences professionnelles à l'ostéopathie
A15: Sage-femme diplômé(e) | B15: 5 à 10 ans | C15: Hospitalier | D15: 4 | E15: 4 | F15: 4 | G15: Non | H15: Oui, occasionnellement (> ou = à 1 fois par mois) | I15: Douleurs lombaires et/ou pelviennes, Post-partum | J15: 4 | K15: Interrogatoire, Examen clinique | L15: Occasionnellement (> ou = à 1 fois par mois) | M15: Oui | N15: Sous-estimation des plaintes des patientes, Difficultés d’accès aux thérapies non médicamenteuses | O15: Exercices/Etirements | P15: Ostéopathie | Q15: Ceinture de maintien/Support pelvien | R15: Conseils posturaux | S15: Repos/Limitation de mouvement | T15: Traitements médicamenteux (antalgiques/analgésiques) | U15: 4 | V15: En cas d’absence de réussite d’autres prises en charge | W15: 1 | X15: Preuves scientifiques, Médiatisation/Réseaux sociaux, Intégration de l’ostéopathie dans les structures de santé | Y15: Insuffisance de preuves scientifiques, Insuffisance de collaboration interprofessionnelle avec des ostéopathes | Z15: Convictions personnelles concernant cette approche thérapeutique, Expérience personnelle antérieure positive ou négative avec l’ostéopathie | AA15: Non | AB15: Oui | AC15: Oui | AD15: Mise en place de protocoles règlementés, Encadrement institutionnel et recommandations officielles | AE15: 0 | AF15: 0 | AG15: 0 | AH15: 0 | AI15: 0 | AJ15: 0
A16: Sage-femme diplômé(e) | B16: 5 à 10 ans | C16: Hospitalier | D16: 3 | E16: 5 | F16: 4 | G16: Non | H16: Oui, occasionnellement (> ou = à 1 fois par mois) | I16: Préparation à l’accouchement, Post-partum | J16: 5 | K16: Interrogatoire, Examen clinique | L16: Occasionnellement (> ou = à 1 fois par mois) | M16: Oui | N16: Assimilation du syndrome à des lombalgies non spécifiques | O16: Ostéopathie | P16: Conseils posturaux | Q16: Traitements médicamenteux (antalgiques/analgésiques) | R16: Exercices/Etirements | S16: Ceinture de maintien/Support pelvien | T16: Repos/Limitation de mouvement | U16: 5 | V16: Dès les premiers symptômes | W16: 2 | X16: Contenus pédagogiques sur les principes ostéopathiques inscrits au parcours académique, Intégration de l’ostéopathie dans les structures de santé | Y16: Peu de contenus pédagogiques sur les principes ostéopathiques inscrits au parcours académique, Insuffisance de collaboration interprofessionnelle avec des ostéopathes, Coût pour les patientes | Z16: Caractère chronique ou aigu des douleurs, Spécialisation de l’ostéopathe en périnatalité, Motivation des patientes pour une prise en charge manuelle complémentaire, Disponibilité et/ou accessibilité d’ostéopathes dans votre réseau | AA16: Non | AB16: Oui | AC16: Oui | AD16: Demande des patientes, Encadrement institutionnel et recommandations officielles | AE16: 0 | AF16: 0 | AG16: 0 | AH16: 0 | AI16: 0 | AJ16: 0
A17: Sage-femme diplômé(e) | B17: 5 à 10 ans | C17: Hospitalier | D17: 2 | E17: 3 | F17: 2 | G17: Non | H17: Oui, rarement (< à 1 fois par mois) | I17: Post-partum | J17: 3 | K17: Interrogatoire, Examen clinique | L17: Occasionnellement (> ou = à 1 fois par mois) | M17: Sans avis | N17: 0 | O17: Exercices/Etirements | P17: Traitements médicamenteux (antalgiques/analgésiques) | Q17: Ostéopathie, Conseils posturaux | R17: Ceinture de maintien/Support pelvien | S17: Repos/Limitation de mouvement | T17: Traitements médicamenteux (antalgiques/analgésiques) | U17: 4 | V17: Dès les premiers symptômes | W17: 2 | X17: Contenus pédagogiques sur les principes ostéopathiques inscrits au parcours académique, Preuves scientifiques, Réduction du coût des séances pour les patientes, Reconnaissance institutionnelle, Intégration de l’ostéopathie dans les structures de santé | Y17: Peu de contenus pédagogiques sur les principes ostéopathiques inscrits au parcours académique, Absence de connaissances sur la pratique ostéopathique, Insuffisance de preuves scientifiques, Insuffisance de collaboration interprofessionnelle avec des ostéopathes, Coût pour les patientes, Absence de reconnaissance institutionnelle | Z17: Spécialisation de l’ostéopathe en périnatalité, Motivation des patientes pour une prise en charge manuelle complémentaire, Expérience personnelle antérieure positive ou négative avec l’ostéopathie | AA17: Oui | AB17: Oui | AC17: Oui | AD17: Preuves de résultats positifs des traitements ostéopathiques, Mise en place de protocoles règlementés, Encadrement institutionnel et recommandations officielles | AE17: 0 | AF17: 0 | AG17: 0 | AH17: 0 | AI17: 0 | AJ17: 0
A18: Sage-femme diplômé(e) | B18: Plus de 10 ans | C18: Hospitalier | D18: 3 | E18: 3 | F18: 3 | G18: Non | H18: Oui, occasionnellement (> ou = à 1 fois par mois) | I18: Douleurs lombaires et/ou pelviennes, Post-partum, Fertilité | J18: 4 | K18: Interrogatoire, Examen clinique, En excluant d’autres causes possibles de douleurs pelviennes pendant la grossesse | L18: Fréquemment (> ou = à 1 fois par semaine) | M18: Oui | N18: Assimilation du syndrome à des lombalgies non spécifiques, Sous-estimation des plaintes des patientes, Absence de recommandations professionnelles claires | O18: Conseils posturaux | P18: Traitements médicamenteux (antalgiques/analgésiques) | Q18: Ostéopathie | R18: Ceinture de maintien/Support pelvien | S18: Repos/Limitation de mouvement | T18: Exercices/Etirements | U18: 5 | V18: Dès les premiers symptômes | W18: 2 | X18: Contenus pédagogiques sur les principes ostéopathiques inscrits au parcours académique, Retours de patientes, Intégration de l’ostéopathie dans les structures de santé | Y18: Insuffisance de preuves scientifiques, Insuffisance de collaboration interprofessionnelle avec des ostéopathes | Z18: Réponse ou non aux autres traitements, Spécialisation de l’ostéopathe en périnatalité, Convictions personnelles concernant cette approche thérapeutique | AA18: Oui | AB18: Oui | AC18: Oui | AD18: Preuves de résultats positifs des traitements ostéopathiques | AE18: 0 | AF18: 0 | AG18: 0 | AH18: 0 | AI18: 0 | AJ18: 0
A19: Sage-femme diplômé(e) | B19: 2 à 5 ans | C19: Hospitalier | D19: 2 | E19: 3 | F19: 3 | G19: Non | H19: Oui, occasionnellement (> ou = à 1 fois par mois) | I19: Douleurs lombaires et/ou pelviennes, Post-partum | J19: 5 | K19: Interrogatoire, Examen clinique | L19: Fréquemment (> ou = à 1 fois par semaine) | M19: Non | N19: 0 | O19: Exercices/Etirements | P19: Conseils posturaux | Q19: Ceinture de maintien/Support pelvien | R19: Traitements médicamenteux (antalgiques/analgésiques) | S19: Ostéopathie | T19: Repos/Limitation de mouvement | U19: 4 | V19: Dès les premiers symptômes | W19: 3 | X19: Contenus pédagogiques sur les principes ostéopathiques inscrits au parcours académique, Preuves scientifiques, Reconnaissance institutionnelle | Y19: Insuffisance de preuves scientifiques, Absence de reconnaissance institutionnelle | Z19: Réponse ou non aux autres traitements | AA19: Oui | AB19: Oui | AC19: Oui | AD19: Preuves de résultats positifs des traitements ostéopathiques, Mise en place de protocoles règlementés, Encadrement institutionnel et recommandations officielles | AE19: 0 | AF19: 0 | AG19: 0 | AH19: 0 | AI19: 0 | AJ19: 0
A20: Sage-femme diplômé(e) | B20: 5 à 10 ans | C20: Hospitalier | D20: 1 | E20: 4 | F20: 2 | G20: Sans avis | H20: Non | I20: 0 | J20: 2 | K20: En excluant d’autres causes possibles de douleurs pelviennes pendant la grossesse | L20: Occasionnellement (> ou = à 1 fois par mois) | M20: Sans avis | N20: 0 | O20: Repos/Limitation de mouvement | P20: Exercices/Etirements | Q20: Conseils posturaux | R20: Ostéopathie | S20: Ceinture de maintien/Support pelvien | T20: Traitements médicamenteux (antalgiques/analgésiques) | U20: 5 | V20: En cas d’absence de réussite d’autres prises en charge | W20: 3 | X20: Contenus pédagogiques sur les principes ostéopathiques inscrits au parcours académique, Retours de patientes, Preuves scientifiques, Médiatisation/Réseaux sociaux, Réduction du coût des séances pour les patientes, Reconnaissance institutionnelle, Intégration de l’ostéopathie dans les structures de santé | Y20: Peu de contenus pédagogiques sur les principes ostéopathiques inscrits au parcours académique, Absence de connaissances sur la pratique ostéopathique | Z20: Caractère chronique ou aigu des douleurs, Réponse ou non aux autres traitements, Spécialisation de l’ostéopathe en périnatalité | AA20: Sans avis | AB20: Oui | AC20: Oui | AD20: Preuves de résultats positifs des traitements ostéopathiques, Demande des patientes | AE20: 0 | AF20: 0 | AG20: 0 | AH20: 0 | AI20: 0 | AJ20: 0
A21: Sage-femme diplômé(e) | B21: Moins de 2 ans | C21: Hospitalier | D21: 4 | E21: 5 | F21: 3 | G21: Non | H21: Non | I21: 0 | J21: 3 | K21: Interrogatoire, Examen clinique | L21: Rarement (> ou = à 1 fois tous les 3 mois) | M21: Oui | N21: Absence de formation spécifique sur le syndrome, Assimilation du syndrome à des lombalgies non spécifiques, Sous-estimation des plaintes des patientes | O21: Repos/Limitation de mouvement | P21: Repos/Limitation de mouvement | Q21: Repos/Limitation de mouvement | R21: Ceinture de maintien/Support pelvien | S21: Ceinture de maintien/Support pelvien | T21: Ceinture de maintien/Support pelvien | U21: 5 | V21: Dès les premiers symptômes | W21: 2 | X21: Contenus pédagogiques sur les principes ostéopathiques inscrits au parcours académique, Médiatisation/Réseaux sociaux, Réduction du coût des séances pour les patientes, Intégration de l’ostéopathie dans les structures de santé | Y21: Peu de contenus pédagogiques sur les principes ostéopathiques inscrits au parcours académique, Absence de connaissances sur la pratique ostéopathique, Insuffisance de preuves scientifiques | Z21: Spécialisation de l’ostéopathe en périnatalité, Motivation des patientes pour une prise en charge manuelle complémentaire, Moment de la douleur, Disponibilité et/ou accessibilité d’ostéopathes dans votre réseau, Convictions personnelles concernant cette approche thérapeutique | AA21: Sans avis | AB21: Oui | AC21: Oui | AD21: Preuves de résultats positifs des traitements ostéopathiques, Demande des patientes | AE21: 0 | AF21: 0 | AG21: 0 | AH21: 0 | AI21: 0 | AJ21: 0
A22: Sage-femme diplômé(e) | B22: Plus de 10 ans | C22: Hospitalier | D22: 3 | E22: 2 | F22: 3 | G22: Non | H22: Non | I22: 0 | J22: 4 | K22: Interrogatoire, Examen clinique, En excluant d’autres causes possibles de douleurs pelviennes pendant la grossesse | L22: Occasionnellement (> ou = à 1 fois par mois) | M22: Non | N22: 0 | O22: Conseils posturaux | P22: Ceinture de maintien/Support pelvien | Q22: Ostéopathie | R22: Traitements médicamenteux (antalgiques/analgésiques) | S22: Exercices/Etirements | T22: Repos/Limitation de mouvement | U22: 3 | V22: En cas d’absence de réussite d’autres prises en charge | W22: 2 | X22: Preuves scientifiques, Reconnaissance institutionnelle, Intégration de l’ostéopathie dans les structures de santé | Y22: Insuffisance de preuves scientifiques, Insuffisance de collaboration interprofessionnelle avec des ostéopathes, Absence de reconnaissance institutionnelle | Z22: Réponse ou non aux autres traitements, Spécialisation de l’ostéopathe en périnatalité, Motivation des patientes pour une prise en charge manuelle complémentaire, Collaboration interprofessionnelle préexistante, Convictions personnelles concernant cette approche thérapeutique | AA22: Oui | AB22: Oui | AC22: Oui | AD22: Demande des patientes, Formations sémiologiques supplémentaires des ostéopathes, Mise en place de protocoles règlementés, Encadrement institutionnel et recommandations officielles | AE22: 0 | AF22: 0 | AG22: 0 | AH22: 0 | AI22: 0 | AJ22: 0
A23: Sage-femme diplômé(e) | B23: Plus de 10 ans | C23: Hospitalier | D23: 1 | E23: 4 | F23: 1 | G23: Non | H23: Non | I23: 0 | J23: 3 | K23: Interrogatoire, Examen clinique, En excluant d’autres causes possibles de douleurs pelviennes pendant la grossesse | L23: Rarement (> ou = à 1 fois tous les 3 mois) | M23: Oui | N23: Absence de formation spécifique sur le syndrome, Assimilation du syndrome à des lombalgies non spécifiques, Sous-estimation des plaintes des patientes, Difficultés d’accès aux thérapies non médicamenteuses, Absence de recommandations professionnelles claires | O23: Exercices/Etirements | P23: Traitements médicamenteux (antalgiques/analgésiques) | Q23: Conseils posturaux | R23: Ceinture de maintien/Support pelvien | S23: Repos/Limitation de mouvement | T23: Ostéopathie | U23: 4 | V23: Dès les premiers symptômes | W23: 1 | X23: Retours de patientes, Preuves scientifiques, Réduction du coût des séances pour les patientes, Intégration de l’ostéopathie dans les structures de santé | Y23: Absence de connaissances sur la pratique ostéopathique, Insuffisance de preuves scientifiques | Z23: Réponse ou non aux autres traitements, Collaboration interprofessionnelle préexistante | AA23: Sans avis | AB23: Sans avis | AC23: Sans avis | AD23: Mise en place de protocoles règlementés | AE23: 0 | AF23: 0 | AG23: 0 | AH23: 0 | AI23: 0 | AJ23: 0
A24: Sage-femme diplômé(e) | B24: Plus de 10 ans | C24: Hospitalier | D24: 2 | E24: 3 | F24: 4 | G24: Oui | H24: Oui, rarement (< à 1 fois par mois) | I24: Douleurs lombaires et/ou pelviennes, Post-partum, Sphère émotionnelle | J24: 5 | K24: Interrogatoire, Examen clinique, En excluant d’autres causes possibles de douleurs pelviennes pendant la grossesse | L24: Occasionnellement (> ou = à 1 fois par mois) | M24: Non | N24: 0 | O24: Conseils posturaux | P24: Exercices/Etirements | Q24: Traitements médicamenteux (antalgiques/analgésiques) | R24: Ceinture de maintien/Support pelvien | S24: Ostéopathie | T24: Repos/Limitation de mouvement | U24: 3 | V24: En cas d’absence de réussite d’autres prises en charge | W24: 4 | X24: Preuves scientifiques, Réduction du coût des séances pour les patientes, Reconnaissance institutionnelle | Y24: Insuffisance de preuves scientifiques, Coût pour les patientes, Absence de reconnaissance institutionnelle | Z24: Réponse ou non aux autres traitements, Motivation des patientes pour une prise en charge manuelle complémentaire, Disponibilité et/ou accessibilité d’ostéopathes dans votre réseau, Collaboration interprofessionnelle préexistante, Coût pour les patientes | AA24: Oui | AB24: Sans avis | AC24: Sans avis | AD24: Preuves de résultats positifs des traitements ostéopathiques, Mise en place de protocoles règlementés, Encadrement institutionnel et recommandations officielles | AE24: 0 | AF24: 0 | AG24: en ai bénéficié personnellement mais sans effet notable, hormis moment d'écoute et de réassurance, j'étais plutôt favorable à cette pratique mais l'absence de preuves scientifiques et le coût de la.séance inaccessible à une partie de nos patientes m'empêchent de le conseiller à large échelle. malgré tout ai une consœur formée, à qui j'adresse des patientes en cas d'échec d'autres solutions car pris en charge comme une consultation sage-femme à l'hôpital | AH24: Bénéfices subjectifs, Insuffisance de preuves scientifiques, Coût pout les patientes, Collaboration interprofessionnelle, | AI24: 0 | AJ24: 0
A25: Sage-femme diplômé(e) | B25: Plus de 10 ans | C25: Hospitalier | D25: 2 | E25: 2 | F25: 1 | G25: Non | H25: Non | I25: Douleurs lombaires et/ou pelviennes, Post-partum | J25: 3 | K25: Interrogatoire, Examen clinique, En excluant d’autres causes possibles de douleurs pelviennes pendant la grossesse | L25: Fréquemment (> ou = à 1 fois par semaine) | M25: Non | N25: 0 | O25: Conseils posturaux | P25: Traitements médicamenteux (antalgiques/analgésiques) | Q25: Ostéopathie | R25: Exercices/Etirements | S25: Ceinture de maintien/Support pelvien | T25: Repos/Limitation de mouvement | U25: 3 | V25: En cas d’absence de réussite d’autres prises en charge | W25: 2 | X25: Réduction du coût des séances pour les patientes | Y25: Coût pour les patientes | Z25: Réponse ou non aux autres traitements, Spécialisation de l’ostéopathe en périnatalité, Motivation des patientes pour une prise en charge manuelle complémentaire | AA25: Sans avis | AB25: Sans avis | AC25: Non | AD25: Mise en place de protocoles règlementés | AE25: 0 | AF25: 0 | AG25: 0 | AH25: 0 | AI25: 0 | AJ25: 0
A26: Sage-femme diplômé(e) | B26: Plus de 10 ans | C26: Libéral | D26: 2 | E26: 5 | F26: 4 | G26: Oui | H26: Oui, régulièrement (> ou = à 1 fois par semaine) | I26: Suivi prénatal de grossesse, Préparation à l’accouchement, Douleurs lombaires et/ou pelviennes, Post-partum | J26: 2 | K26: En excluant d’autres causes possibles de douleurs pelviennes pendant la grossesse | L26: Rarement (> ou = à 1 fois tous les 3 mois) | M26: Oui | N26: Sous-estimation des plaintes des patientes, Absence de recommandations professionnelles claires | O26: Exercices/Etirements | P26: Conseils posturaux | Q26: Ostéopathie | R26: Ceinture de maintien/Support pelvien | S26: Traitements médicamenteux (antalgiques/analgésiques) | T26: Repos/Limitation de mouvement | U26: 3 | V26: En cas d’absence de réussite d’autres prises en charge | W26: 4 | X26: Preuves scientifiques | Y26: Peu de contenus pédagogiques sur les principes ostéopathiques inscrits au parcours académique, Insuffisance de preuves scientifiques, Absence de reconnaissance institutionnelle | Z26: Motivation des patientes pour une prise en charge manuelle complémentaire | AA26: Non | AB26: Oui | AC26: Oui | AD26: Mise en place de protocoles règlementés, Encadrement institutionnel et recommandations officielles | AE26: 0 | AF26: 0 | AG26: 0 | AH26: 0 | AI26: 0 | AJ26: 0
A27: Sage-femme diplômé(e) | B27: Plus de 10 ans | C27: Mixte | D27: 4 | E27: 1 | F27: 4 | G27: Oui | H27: Non | I27: 0 | J27: 5 | K27: Interrogatoire, Examen clinique, En excluant d’autres causes possibles de douleurs pelviennes pendant la grossesse | L27: Occasionnellement (> ou = à 1 fois par mois) | M27: Oui | N27: Absence de formation spécifique sur le syndrome, Assimilation du syndrome à des lombalgies non spécifiques, Sous-estimation des plaintes des patientes, Absence de recommandations professionnelles claires | O27: Exercices/Etirements | P27: Traitements médicamenteux (antalgiques/analgésiques) | Q27: Conseils posturaux | R27: Ceinture de maintien/Support pelvien | S27: Ostéopathie | T27: Repos/Limitation de mouvement | U27: 2 | V27: 0 | W27: 1 | X27: Preuves scientifiques | Y27: Insuffisance de preuves scientifiques | Z27: Motivation des patientes pour une prise en charge manuelle complémentaire, Convictions personnelles concernant cette approche thérapeutique | AA27: Oui | AB27: Non | AC27: Non | AD27: Preuves de résultats positifs des traitements ostéopathiques, Encadrement institutionnel et recommandations officielles | AE27: 0 | AF27: 0 | AG27: Actes hors nomenclature à l'efficacité non proouvée, ce serait une forme d'abus de faiblesse de laisser des patientes dépenser de l'argent en leur faisant croire que ça va les aider. | AH27: Insuffisance de preuves scientifiques, Freins éthiques et scientifiques | AI27: aujourd'hui les instances de référence (santé.gouv, inserm, ... alertenet sur les dangers de la pratique de l'ostéopathie. Les bénéfices ne sont pas avérés alors que les risques, complications et retards de prise en charge sont réels. Je ne reccomande plus la pratique de l'ostéopathie à mes patientes et encore moins pour les bébés | AJ27: Insuffisance de preuves scientifiques, Non recommandation institutionnelle de l'ostéopathie, Convictions personnelles, Présence de réticences professionnelles à l'ostéopathie
A28: Sage-femme diplômé(e) | B28: Plus de 10 ans | C28: Hospitalier | D28: 1 | E28: 3 | F28: 1 | G28: Oui | H28: Oui, rarement (< à 1 fois par mois) | I28: Suivi prénatal de grossesse, Douleurs lombaires et/ou pelviennes, Post-partum, Allaitement | J28: 3 | K28: Interrogatoire, Examen clinique, En excluant d’autres causes possibles de douleurs pelviennes pendant la grossesse | L28: Fréquemment (> ou = à 1 fois par semaine) | M28: Sans avis | N28: Sous-estimation des plaintes des patientes, Absence de recommandations professionnelles claires | O28: Exercices/Etirements | P28: Ostéopathie | Q28: Conseils posturaux | R28: Ceinture de maintien/Support pelvien | S28: Traitements médicamenteux (antalgiques/analgésiques) | T28: Repos/Limitation de mouvement | U28: 4 | V28: En cas d’absence de réussite d’autres prises en charge | W28: 4 | X28: Retours de patientes, Preuves scientifiques, Réduction du coût des séances pour les patientes, Reconnaissance institutionnelle, Intégration de l’ostéopathie dans les structures de santé | Y28: Insuffisance de preuves scientifiques, Insuffisance de collaboration interprofessionnelle avec des ostéopathes, Coût pour les patientes | Z28: Caractère chronique ou aigu des douleurs, Réponse ou non aux autres traitements, Motivation des patientes pour une prise en charge manuelle complémentaire, Disponibilité et/ou accessibilité d’ostéopathes dans votre réseau, Convictions personnelles concernant cette approche thérapeutique, Expérience personnelle antérieure positive ou négative avec l’ostéopathie | AA28: Non | AB28: Oui | AC28: Oui | AD28: Preuves de résultats positifs des traitements ostéopathiques, Demande des patientes, Absence ou inefficacité d’autres solutions thérapeutiques | AE28: Souvent ça soulage mais sur une courte durée | AF28: Efficacité perçue, Soulagement temporaire | AG28: Les sages-femmes sont majoritairement pro-ostéopathie | AH28: Favorable à l'intégration de l'ostéopathie | AI28: La prise en charge doit toujours être globale et pluridisciplinaire (osteo, kiné, sf, médecin, acupuncture...) | AJ28: Collaboration interprofessionnelle, Favorable à l'intégration de l'ostéopathie
A29: Sage-femme diplômé(e) | B29: Moins de 2 ans | C29: Hospitalier | D29: 3 | E29: 5 | F29: 3 | G29: Oui | H29: Oui, occasionnellement (> ou = à 1 fois par mois) | I29: Suivi prénatal de grossesse, Douleurs lombaires et/ou pelviennes, Post-partum | J29: 3 | K29: Interrogatoire, Examen clinique, En excluant d’autres causes possibles de douleurs pelviennes pendant la grossesse | L29: Rarement (> ou = à 1 fois tous les 3 mois) | M29: Oui | N29: Absence de formation spécifique sur le syndrome, Assimilation du syndrome à des lombalgies non spécifiques | O29: Exercices/Etirements | P29: Ostéopathie | Q29: Conseils posturaux | R29: Ceinture de maintien/Support pelvien | S29: Repos/Limitation de mouvement | T29: Traitements médicamenteux (antalgiques/analgésiques) | U29: 5 | V29: Prise en charge prénatale et post-partum | W29: 2 | X29: Contenus pédagogiques sur les principes ostéopathiques inscrits au parcours académique, Retours de patientes, Preuves scientifiques, Réduction du coût des séances pour les patientes, Intégration de l’ostéopathie dans les structures de santé | Y29: Peu de contenus pédagogiques sur les principes ostéopathiques inscrits au parcours académique, Coût pour les patientes | Z29: Motivation des patientes pour une prise en charge manuelle complémentaire, Collaboration interprofessionnelle préexistante, Convictions personnelles concernant cette approche thérapeutique, Expérience personnelle antérieure positive ou négative avec l’ostéopathie | AA29: Non | AB29: Oui | AC29: Oui | AD29: Mise en place de protocoles règlementés, Encadrement institutionnel et recommandations officielles | AE29: 0 | AF29: 0 | AG29: 0 | AH29: 0 | AI29: 0 | AJ29: 0
A30: Sage-femme diplômé(e) | B30: Plus de 10 ans | C30: Libéral | D30: 4 | E30: 5 | F30: 4 | G30: Oui | H30: Oui, régulièrement (> ou = à 1 fois par semaine) | I30: Suivi prénatal de grossesse, Préparation à l’accouchement, Douleurs lombaires et/ou pelviennes, Troubles digestifs associés, Post-partum, Fertilité, Allaitement, Sphère émotionnelle | J30: 3 | K30: Interrogatoire, Examen clinique, En excluant d’autres causes possibles de douleurs pelviennes pendant la grossesse | L30: Fréquemment (> ou = à 1 fois par semaine) | M30: Sans avis | N30: 0 | O30: Exercices/Etirements | P30: Ostéopathie | Q30: Conseils posturaux | R30: Repos/Limitation de mouvement | S30: Ceinture de maintien/Support pelvien | T30: Traitements médicamenteux (antalgiques/analgésiques) | U30: 5 | V30: Dès les premiers symptômes | W30: 3 | X30: Preuves scientifiques, Réduction du coût des séances pour les patientes, Reconnaissance institutionnelle | Y30: Insuffisance de preuves scientifiques, Coût pour les patientes, Absence de reconnaissance institutionnelle | Z30: Caractère chronique ou aigu des douleurs, Motivation des patientes pour une prise en charge manuelle complémentaire | AA30: Non | AB30: Oui | AC30: Oui | AD30: Preuves de résultats positifs des traitements ostéopathiques, Encadrement institutionnel et recommandations officielles | AE30: 0 | AF30: 0 | AG30: 0 | AH30: 0 | AI30: 0 | AJ30: 0
A31: Sage-femme diplômé(e) | B31: Moins de 2 ans | C31: Hospitalier | D31: 1 | E31: 1 | F31: 2 | G31: Sans avis | H31: Non | I31: 0 | J31: 3 | K31: Interrogatoire, Examen clinique, En excluant d’autres causes possibles de douleurs pelviennes pendant la grossesse | L31: Occasionnellement (> ou = à 1 fois par mois) | M31: Sans avis | N31: 0 | O31: Exercices/Etirements | P31: Traitements médicamenteux (antalgiques/analgésiques) | Q31: Conseils posturaux | R31: Ceinture de maintien/Support pelvien | S31: Repos/Limitation de mouvement | T31: Ostéopathie | U31: 1 | V31: 0 | W31: 3 | X31: 0 | Y31: Absence de reconnaissance institutionnelle, Insuffisance de preuves scientifiques | Z31: Convictions personnelles concernant cette approche thérapeutique | AA31: Sans avis | AB31: Non | AC31: Non | AD31: Preuves de résultats positifs des traitements ostéopathiques | AE31: 0 | AF31: 0 | AG31: 0 | AH31: 0 | AI31: 0 | AJ31: 0
A32: Sage-femme diplômé(e) | B32: Plus de 10 ans | C32: Libéral | D32: 4 | E32: 5 | F32: 4 | G32: Oui | H32: Oui, régulièrement (> ou = à 1 fois par semaine) | I32: Suivi prénatal de grossesse, Douleurs lombaires et/ou pelviennes, Post-partum, Fertilité | J32: 4 | K32: Interrogatoire, En excluant d’autres causes possibles de douleurs pelviennes pendant la grossesse | L32: Occasionnellement (> ou = à 1 fois par mois) | M32: Sans avis | N32: Assimilation du syndrome à des lombalgies non spécifiques, Sous-estimation des plaintes des patientes, Absence de recommandations professionnelles claires | O32: Ceinture de maintien/Support pelvien | P32: Ostéopathie | Q32: Exercices/Etirements | R32: Conseils posturaux | S32: Traitements médicamenteux (antalgiques/analgésiques) | T32: Repos/Limitation de mouvement | U32: 4 | V32: Dès les premiers symptômes | W32: 3 | X32: Preuves scientifiques, Reconnaissance institutionnelle, Intégration de l’ostéopathie dans les structures de santé | Y32: Insuffisance de preuves scientifiques, Coût pour les patientes | Z32: Spécialisation de l’ostéopathe en périnatalité, Motivation des patientes pour une prise en charge manuelle complémentaire, Collaboration interprofessionnelle préexistante, Expérience personnelle antérieure positive ou négative avec l’ostéopathie | AA32: Sans avis | AB32: Oui | AC32: Oui | AD32: Preuves de résultats positifs des traitements ostéopathiques, Demande des patientes, Formations sémiologiques supplémentaires des ostéopathes, Encadrement institutionnel et recommandations officielles | AE32: 0 | AF32: 0 | AG32: J ai eu la chance de collaborer à l’hôpital avec une ostéopathe qui venait proposer des consultations au sein de laMaternité et plus tard en cabinet libéral avec une collègue osteo, amis aussi des sage-femmes ostéopathes( deux formation distinctes) | AH32: Collaboration interprofessionnelle, Favorable à l'intégration de l'ostéopathie | AI32: 0 | AJ32: 0
A33: Sage-femme diplômé(e) | B33: Plus de 10 ans | C33: Hospitalier | D33: 4 | E33: 5 | F33: 4 | G33: Non | H33: Non | I33: 0 | J33: 4 | K33: Interrogatoire, Examen clinique, En excluant d’autres causes possibles de douleurs pelviennes pendant la grossesse | L33: Fréquemment (> ou = à 1 fois par semaine) | M33: Oui | N33: Absence de formation spécifique sur le syndrome, Sous-estimation des plaintes des patientes, Difficultés d’accès aux thérapies non médicamenteuses | O33: Traitements médicamenteux (antalgiques/analgésiques) | P33: Ostéopathie | Q33: Conseils posturaux | R33: Ceinture de maintien/Support pelvien | S33: Exercices/Etirements | T33: Repos/Limitation de mouvement | U33: 5 | V33: Dès les premiers symptômes | W33: 3 | X33: Réduction du coût des séances pour les patientes, Reconnaissance institutionnelle, Intégration de l’ostéopathie dans les structures de santé | Y33: Absence de connaissances sur la pratique ostéopathique, Insuffisance de collaboration interprofessionnelle avec des ostéopathes, Coût pour les patientes, Absence de reconnaissance institutionnelle | Z33: Caractère chronique ou aigu des douleurs, Réponse ou non aux autres traitements, Motivation des patientes pour une prise en charge manuelle complémentaire, Disponibilité et/ou accessibilité d’ostéopathes dans votre réseau, Convictions personnelles concernant cette approche thérapeutique, Expérience personnelle antérieure positive ou négative avec l’ostéopathie | AA33: Non | AB33: Oui | AC33: Oui | AD33: Demande des patientes, Encadrement institutionnel et recommandations officielles | AE33: 0 | AF33: 0 | AG33: 0 | AH33: 0 | AI33: 0 | AJ33: 0
A34: Sage-femme diplômé(e) | B34: 2 à 5 ans | C34: Libéral | D34: 4 | E34: 5 | F34: 4 | G34: Oui | H34: Oui, régulièrement (> ou = à 1 fois par semaine) | I34: Suivi prénatal de grossesse, Préparation à l’accouchement, Douleurs lombaires et/ou pelviennes, Troubles digestifs associés, Post-partum | J34: 4 | K34: Interrogatoire, En excluant d’autres causes possibles de douleurs pelviennes pendant la grossesse | L34: Occasionnellement (> ou = à 1 fois par mois) | M34: Oui | N34: Absence de formation spécifique sur le syndrome, Assimilation du syndrome à des lombalgies non spécifiques, Sous-estimation des plaintes des patientes, Difficultés d’accès aux thérapies non médicamenteuses, Absence de recommandations professionnelles claires | O34: Ostéopathie | P34: Ceinture de maintien/Support pelvien | Q34: Exercices/Etirements | R34: Conseils posturaux | S34: Traitements médicamenteux (antalgiques/analgésiques) | T34: Repos/Limitation de mouvement | U34: 5 | V34: Dès les premiers symptômes | W34: 2 | X34: Contenus pédagogiques sur les principes ostéopathiques inscrits au parcours académique, Preuves scientifiques, Reconnaissance institutionnelle, Intégration de l’ostéopathie dans les structures de santé | Y34: Peu de contenus pédagogiques sur les principes ostéopathiques inscrits au parcours académique, Absence de connaissances sur la pratique ostéopathique, Insuffisance de preuves scientifiques, Insuffisance de collaboration interprofessionnelle avec des ostéopathes, Coût pour les patientes, Absence de reconnaissance institutionnelle | Z34: Caractère chronique ou aigu des douleurs, Réponse ou non aux autres traitements, Motivation des patientes pour une prise en charge manuelle complémentaire, Disponibilité et/ou accessibilité d’ostéopathes dans votre réseau, Convictions personnelles concernant cette approche thérapeutique, Expérience personnelle antérieure positive ou négative avec l’ostéopathie | AA34: Non | AB34: Oui | AC34: Oui | AD34: Preuves de résultats positifs des traitements ostéopathiques, Formations sémiologiques supplémentaires des ostéopathes, Recommandations par d’autres professionnels de santé, Mise en place de protocoles règlementés, Encadrement institutionnel et recommandations officielles | AE34: Je trouve que dans la plupart des cas, mes patientes sont soulagées avec peu de séances ! Mais parfois le côté "mécanique" de la grossesse et e la posture de l'enfant est impossible à dépasser... | AF34: Efficacité perçue, Limites des pratiques ostéopathiques | AG34: Notre cabinet collabore volontiers et de façon systématique. Les SF du Haut Rhin en général sont ouvertes à cette collaboration je pense. | AH34: Collaboration interprofessionnelle, Favorable à l'intégration de l'ostéopathie | AI34: 0 | AJ34: 0
